Workbook

Sheet Summary
A1: XAUUSD daily log — summary
A2: Source: Spot XAU/USD (Twelve Data). Updated automatically after each trading day.
A3: Measure | B3: Value | C3: Note
A4: Days logged | B4: =COUNTA('Daily log'!A:A)-1 | C4: Trading days in the log
A5: Latest date | B5: =INDEX('Daily log'!A:A,$B$4+1)
A6: Latest close ($) | B6: =INDEX('Daily log'!F:F,$B$4+1)
A7: Day change ($) | B7: =INDEX('Daily log'!G:G,$B$4+1)
A8: Day change (%) | B8: =INDEX('Daily log'!H:H,$B$4+1)
A9: 1 week change (%) | B9: =IFERROR(B6/INDEX('Daily log'!F:F,$B$4+1-5)-1,"") | C9: Versus 5 trading days ago
A10: 1 month change (%) | B10: =IFERROR(B6/INDEX('Daily log'!F:F,$B$4+1-21)-1,"") | C10: Versus 21 trading days ago
A11: 3 month change (%) | B11: =IFERROR(B6/INDEX('Daily log'!F:F,$B$4+1-63)-1,"") | C11: Versus 63 trading days ago
A12: Year to date (%) | B12: =IFERROR(B6/INDEX('Daily log'!$F$2:$F$100000,MATCH(DATE(YEAR(B5),1,1)-1,'Daily log'!$A$2:$A$100000,1))-1,"") | C12: Versus the last close of the previous year
A13: 52 week high ($) | B13: =_xlfn.MAXIFS('Daily log'!D:D,'Daily log'!A:A,">="&(B5-365))
A14: 52 week low ($) | B14: =_xlfn.MINIFS('Daily log'!E:E,'Daily log'!A:A,">="&(B5-365))
A15: Below 52 week high (%) | B15: =IFERROR(B6/B13-1,"")
A16: Average daily range, 20 days ($) | B16: =IFERROR(AVERAGE(INDEX('Daily log'!I:I,$B$4+1-19):INDEX('Daily log'!I:I,$B$4+1)),"") | C16: High minus low
A17: ATR 14 ($) | B17: =INDEX('Daily log'!K:K,$B$4+1) | C17: Typical daily move
A18: RSI 14 | B18: =INDEX('Daily log'!L:L,$B$4+1) | C18: Above 50 = upward momentum
A19: Trend vs EMA 200 | B19: =INDEX('Daily log'!P:P,$B$4+1) | C19: Above = long-term uptrend
A20: Signals logged | B20: =SUM('Daily log'!R:R) | C20: LONG and SHORT signals from the engine
A21: Net result (R) | B21: =SUM('Daily log'!U:U) | C21: Closed signals only

Sheet Daily log
A1: Date | B1: Day | C1: Open ($) | D1: High ($) | E1: Low ($) | F1: Close ($) | G1: Change ($) | H1: Change (%) | I1: Range ($) | J1: Direction | K1: ATR 14 ($) | L1: RSI 14 | M1: EMA 20 ($) | N1: EMA 50 ($) | O1: EMA 200 ($) | P1: Trend vs EMA 200 | Q1: Volume (COMEX) | R1: Signals | S1: Wins | T1: Losses | U1: Net R
A2: 44473 | B2: =TEXT(A2,"ddd") | C2: 1762.6 | D2: 1771.5 | E2: 1747.7 | F2: 1767.6 | I2: =D2-E2 | J2: =IF(F2>C2,"Up",IF(F2<C2,"Down","Flat")) | P2: =IF(O2="","",IF(F2>O2,"Above","Below")) | Q2: 166180 | R2: 0 | S2: 0 | T2: 0 | U2: 0
A3: 44474 | B3: =TEXT(A3,"ddd") | C3: 1770.8 | D3: 1771.1 | E3: 1748.6 | F3: 1760.9 | G3: =F3-F2 | H3: =IF(F2=0,0,G3/F2) | I3: =D3-E3 | J3: =IF(F3>C3,"Up",IF(F3<C3,"Down","Flat")) | P3: =IF(O3="","",IF(F3>O3,"Above","Below")) | Q3: 151424 | R3: 0 | S3: 0 | T3: 0 | U3: 0
A4: 44475 | B4: =TEXT(A4,"ddd") | C4: 1760.5 | D4: 1765.9 | E4: 1745.4 | F4: 1761.8 | G4: =F4-F3 | H4: =IF(F3=0,0,G4/F3) | I4: =D4-E4 | J4: =IF(F4>C4,"Up",IF(F4<C4,"Down","Flat")) | P4: =IF(O4="","",IF(F4>O4,"Above","Below")) | Q4: 159218 | R4: 0 | S4: 0 | T4: 0 | U4: 0
A5: 44476 | B5: =TEXT(A5,"ddd") | C5: 1763.8 | D5: 1767.7 | E5: 1752 | F5: 1759.2 | G5: =F5-F4 | H5: =IF(F4=0,0,G5/F4) | I5: =D5-E5 | J5: =IF(F5>C5,"Up",IF(F5<C5,"Down","Flat")) | P5: =IF(O5="","",IF(F5>O5,"Above","Below")) | Q5: 146406 | R5: 0 | S5: 0 | T5: 0 | U5: 0
A6: 44477 | B6: =TEXT(A6,"ddd") | C6: 1757 | D6: 1782.4 | E6: 1753.6 | F6: 1757.4 | G6: =F6-F5 | H6: =IF(F5=0,0,G6/F5) | I6: =D6-E6 | J6: =IF(F6>C6,"Up",IF(F6<C6,"Down","Flat")) | P6: =IF(O6="","",IF(F6>O6,"Above","Below")) | Q6: 240371 | R6: 0 | S6: 0 | T6: 0 | U6: 0
A7: 44480 | B7: =TEXT(A7,"ddd") | C7: 1757.4 | D7: 1761.1 | E7: 1749.9 | F7: 1755.7 | G7: =F7-F6 | H7: =IF(F6=0,0,G7/F6) | I7: =D7-E7 | J7: =IF(F7>C7,"Up",IF(F7<C7,"Down","Flat")) | P7: =IF(O7="","",IF(F7>O7,"Above","Below")) | Q7: 114771 | R7: 0 | S7: 0 | T7: 0 | U7: 0
A8: 44481 | B8: =TEXT(A8,"ddd") | C8: 1753.6 | D8: 1770 | E8: 1750.5 | F8: 1759.3 | G8: =F8-F7 | H8: =IF(F7=0,0,G8/F7) | I8: =D8-E8 | J8: =IF(F8>C8,"Up",IF(F8<C8,"Down","Flat")) | P8: =IF(O8="","",IF(F8>O8,"Above","Below")) | Q8: 168110 | R8: 0 | S8: 0 | T8: 0 | U8: 0
A9: 44482 | B9: =TEXT(A9,"ddd") | C9: 1760.4 | D9: 1797.4 | E9: 1757.9 | F9: 1794.7 | G9: =F9-F8 | H9: =IF(F8=0,0,G9/F8) | I9: =D9-E9 | J9: =IF(F9>C9,"Up",IF(F9<C9,"Down","Flat")) | P9: =IF(O9="","",IF(F9>O9,"Above","Below")) | Q9: 299041 | R9: 0 | S9: 0 | T9: 0 | U9: 0
A10: 44483 | B10: =TEXT(A10,"ddd") | C10: 1793.6 | D10: 1801.9 | E10: 1787.6 | F10: 1797.9 | G10: =F10-F9 | H10: =IF(F9=0,0,G10/F9) | I10: =D10-E10 | J10: =IF(F10>C10,"Up",IF(F10<C10,"Down","Flat")) | P10: =IF(O10="","",IF(F10>O10,"Above","Below")) | Q10: 164651 | R10: 0 | S10: 0 | T10: 0 | U10: 0
A11: 44484 | B11: =TEXT(A11,"ddd") | C11: 1797.3 | D11: 1797.7 | E11: 1765.1 | F11: 1768.3 | G11: =F11-F10 | H11: =IF(F10=0,0,G11/F10) | I11: =D11-E11 | J11: =IF(F11>C11,"Up",IF(F11<C11,"Down","Flat")) | P11: =IF(O11="","",IF(F11>O11,"Above","Below")) | Q11: 202631 | R11: 0 | S11: 0 | T11: 0 | U11: 0
A12: 44487 | B12: =TEXT(A12,"ddd") | C12: 1767.5 | D12: 1772.5 | E12: 1760.3 | F12: 1765.7 | G12: =F12-F11 | H12: =IF(F11=0,0,G12/F11) | I12: =D12-E12 | J12: =IF(F12>C12,"Up",IF(F12<C12,"Down","Flat")) | P12: =IF(O12="","",IF(F12>O12,"Above","Below")) | Q12: 152741 | R12: 0 | S12: 0 | T12: 0 | U12: 0
A13: 44488 | B13: =TEXT(A13,"ddd") | C13: 1764.8 | D13: 1786 | E13: 1763.4 | F13: 1770.5 | G13: =F13-F12 | H13: =IF(F12=0,0,G13/F12) | I13: =D13-E13 | J13: =IF(F13>C13,"Up",IF(F13<C13,"Down","Flat")) | P13: =IF(O13="","",IF(F13>O13,"Above","Below")) | Q13: 166972 | R13: 0 | S13: 0 | T13: 0 | U13: 0
A14: 44489 | B14: =TEXT(A14,"ddd") | C14: 1769.4 | D14: 1789.6 | E14: 1767.1 | F14: 1784.9 | G14: =F14-F13 | H14: =IF(F13=0,0,G14/F13) | I14: =D14-E14 | J14: =IF(F14>C14,"Up",IF(F14<C14,"Down","Flat")) | P14: =IF(O14="","",IF(F14>O14,"Above","Below")) | Q14: 174076 | R14: 0 | S14: 0 | T14: 0 | U14: 0
A15: 44490 | B15: =TEXT(A15,"ddd") | C15: 1782.5 | D15: 1790.3 | E15: 1776.8 | F15: 1781.9 | G15: =F15-F14 | H15: =IF(F14=0,0,G15/F14) | I15: =D15-E15 | J15: =IF(F15>C15,"Up",IF(F15<C15,"Down","Flat")) | P15: =IF(O15="","",IF(F15>O15,"Above","Below")) | Q15: 138729 | R15: 0 | S15: 0 | T15: 0 | U15: 0
A16: 44491 | B16: =TEXT(A16,"ddd") | C16: 1783.7 | D16: 1815.5 | E16: 1783.4 | F16: 1796.3 | G16: =F16-F15 | H16: =IF(F15=0,0,G16/F15) | I16: =D16-E16 | J16: =IF(F16>C16,"Up",IF(F16<C16,"Down","Flat")) | K16: 22.88 | L16: 46.8 | P16: =IF(O16="","",IF(F16>O16,"Above","Below")) | Q16: 312812 | R16: 0 | S16: 0 | T16: 0 | U16: 0
A17: 44494 | B17: =TEXT(A17,"ddd") | C17: 1794.2 | D17: 1811.5 | E17: 1793 | F17: 1806.8 | G17: =F17-F16 | H17: =IF(F16=0,0,G17/F16) | I17: =D17-E17 | J17: =IF(F17>C17,"Up",IF(F17<C17,"Down","Flat")) | K17: 22.57 | L17: 51.38 | P17: =IF(O17="","",IF(F17>O17,"Above","Below")) | Q17: 153589 | R17: 0 | S17: 0 | T17: 0 | U17: 0
A18: 44495 | B18: =TEXT(A18,"ddd") | C18: 1808.7 | D18: 1809.8 | E18: 1783 | F18: 1793.4 | G18: =F18-F17 | H18: =IF(F17=0,0,G18/F17) | I18: =D18-E18 | J18: =IF(F18>C18,"Up",IF(F18<C18,"Down","Flat")) | K18: 22.87 | L18: 45.94 | P18: =IF(O18="","",IF(F18>O18,"Above","Below")) | Q18: 197929 | R18: 0 | S18: 0 | T18: 0 | U18: 0
A19: 44496 | B19: =TEXT(A19,"ddd") | C19: 1795 | D19: 1801 | E19: 1784.3 | F19: 1798.8 | G19: =F19-F18 | H19: =IF(F18=0,0,G19/F18) | I19: =D19-E19 | J19: =IF(F19>C19,"Up",IF(F19<C19,"Down","Flat")) | K19: 22.43 | L19: 48.32 | P19: =IF(O19="","",IF(F19>O19,"Above","Below")) | Q19: 182801 | R19: 0 | S19: 0 | T19: 0 | U19: 0
A20: 44497 | B20: =TEXT(A20,"ddd") | C20: 1798.7 | D20: 1812.7 | E20: 1793.1 | F20: 1802.6 | G20: =F20-F19 | H20: =IF(F19=0,0,G20/F19) | I20: =D20-E20 | J20: =IF(F20>C20,"Up",IF(F20<C20,"Down","Flat")) | K20: 22.23 | L20: 49.98 | P20: =IF(O20="","",IF(F20>O20,"Above","Below")) | Q20: 220876 | R20: 0 | S20: 0 | T20: 0 | U20: 0
A21: 44498 | B21: =TEXT(A21,"ddd") | C21: 1801.5 | D21: 1802.9 | E21: 1772.4 | F21: 1783.9 | G21: =F21-F20 | H21: =IF(F20=0,0,G21/F20) | I21: =D21-E21 | J21: =IF(F21>C21,"Up",IF(F21<C21,"Down","Flat")) | K21: 22.82 | L21: 42.69 | M21: 1782.88 | P21: =IF(O21="","",IF(F21>O21,"Above","Below")) | Q21: 254513 | R21: 0 | S21: 0 | T21: 0 | U21: 0
A22: 44501 | B22: =TEXT(A22,"ddd") | C22: 1785.3 | D22: 1797.5 | E22: 1780.2 | F22: 1795.8 | G22: =F22-F21 | H22: =IF(F21=0,0,G22/F21) | I22: =D22-E22 | J22: =IF(F22>C22,"Up",IF(F22<C22,"Down","Flat")) | K22: 22.42 | L22: 47.9 | M22: 1784.11 | P22: =IF(O22="","",IF(F22>O22,"Above","Below")) | Q22: 143332 | R22: 0 | S22: 0 | T22: 0 | U22: 0
A23: 44502 | B23: =TEXT(A23,"ddd") | C23: 1794.8 | D23: 1797.8 | E23: 1787.4 | F23: 1789.4 | G23: =F23-F22 | H23: =IF(F22=0,0,G23/F22) | I23: =D23-E23 | J23: =IF(F23>C23,"Up",IF(F23<C23,"Down","Flat")) | K23: 21.56 | L23: 45.5 | M23: 1784.61 | P23: =IF(O23="","",IF(F23>O23,"Above","Below")) | Q23: 145786 | R23: 0 | S23: 0 | T23: 0 | U23: 0
A24: 44503 | B24: =TEXT(A24,"ddd") | C24: 1789.2 | D24: 1789.3 | E24: 1758.5 | F24: 1763.9 | G24: =F24-F23 | H24: =IF(F23=0,0,G24/F23) | I24: =D24-E24 | J24: =IF(F24>C24,"Up",IF(F24<C24,"Down","Flat")) | K24: 22.23 | L24: 37.47 | M24: 1782.64 | P24: =IF(O24="","",IF(F24>O24,"Above","Below")) | Q24: 257427 | R24: 0 | S24: 0 | T24: 0 | U24: 0
A25: 44504 | B25: =TEXT(A25,"ddd") | C25: 1769.9 | D25: 1800.3 | E25: 1769.3 | F25: 1793.5 | G25: =F25-F24 | H25: =IF(F24=0,0,G25/F24) | I25: =D25-E25 | J25: =IF(F25>C25,"Up",IF(F25<C25,"Down","Flat")) | K25: 23.24 | L25: 48.78 | M25: 1783.67 | P25: =IF(O25="","",IF(F25>O25,"Above","Below")) | Q25: 222609 | R25: 0 | S25: 0 | T25: 0 | U25: 0
A26: 44505 | B26: =TEXT(A26,"ddd") | C26: 1792.6 | D26: 1820.1 | E26: 1785.3 | F26: 1816.8 | G26: =F26-F25 | H26: =IF(F25=0,0,G26/F25) | I26: =D26-E26 | J26: =IF(F26>C26,"Up",IF(F26<C26,"Down","Flat")) | K26: 24.07 | L26: 55.59 | M26: 1786.83 | P26: =IF(O26="","",IF(F26>O26,"Above","Below")) | Q26: 299618 | R26: 0 | S26: 0 | T26: 0 | U26: 0
A27: 44508 | B27: =TEXT(A27,"ddd") | C27: 1820.6 | D27: 1828.3 | E27: 1813.8 | F27: 1828 | G27: =F27-F26 | H27: =IF(F26=0,0,G27/F26) | I27: =D27-E27 | J27: =IF(F27>C27,"Up",IF(F27<C27,"Down","Flat")) | K27: 23.38 | L27: 58.45 | M27: 1790.75 | P27: =IF(O27="","",IF(F27>O27,"Above","Below")) | Q27: 200412 | R27: 0 | S27: 0 | T27: 0 | U27: 0
A28: 44509 | B28: =TEXT(A28,"ddd") | C28: 1826.9 | D28: 1834.8 | E28: 1821 | F28: 1830.8 | G28: =F28-F27 | H28: =IF(F27=0,0,G28/F27) | I28: =D28-E28 | J28: =IF(F28>C28,"Up",IF(F28<C28,"Down","Flat")) | K28: 22.7 | L28: 59.15 | M28: 1794.56 | P28: =IF(O28="","",IF(F28>O28,"Above","Below")) | Q28: 224407 | R28: 0 | S28: 0 | T28: 0 | U28: 0
A29: 44510 | B29: =TEXT(A29,"ddd") | C29: 1834.5 | D29: 1870.6 | E29: 1823 | F29: 1848.3 | G29: =F29-F28 | H29: =IF(F28=0,0,G29/F28) | I29: =D29-E29 | J29: =IF(F29>C29,"Up",IF(F29<C29,"Down","Flat")) | K29: 24.48 | L29: 63.36 | M29: 1799.68 | P29: =IF(O29="","",IF(F29>O29,"Above","Below")) | Q29: 352787 | R29: 0 | S29: 0 | T29: 0 | U29: 0
A30: 44511 | B30: =TEXT(A30,"ddd") | C30: 1851.5 | D30: 1868.7 | E30: 1845.1 | F30: 1863.9 | G30: =F30-F29 | H30: =IF(F29=0,0,G30/F29) | I30: =D30-E30 | J30: =IF(F30>C30,"Up",IF(F30<C30,"Down","Flat")) | K30: 24.42 | L30: 66.65 | M30: 1805.8 | P30: =IF(O30="","",IF(F30>O30,"Above","Below")) | Q30: 205312 | R30: 0 | S30: 0 | T30: 0 | U30: 0
A31: 44512 | B31: =TEXT(A31,"ddd") | C31: 1864.3 | D31: 1871.4 | E31: 1847.5 | F31: 1868.5 | G31: =F31-F30 | H31: =IF(F30=0,0,G31/F30) | I31: =D31-E31 | J31: =IF(F31>C31,"Up",IF(F31<C31,"Down","Flat")) | K31: 24.38 | L31: 67.58 | M31: 1811.77 | P31: =IF(O31="","",IF(F31>O31,"Above","Below")) | Q31: 201358 | R31: 0 | S31: 0 | T31: 0 | U31: 0
A32: 44515 | B32: =TEXT(A32,"ddd") | C32: 1872.6 | D32: 1873 | E32: 1858.5 | F32: 1866.6 | G32: =F32-F31 | H32: =IF(F31=0,0,G32/F31) | I32: =D32-E32 | J32: =IF(F32>C32,"Up",IF(F32<C32,"Down","Flat")) | K32: 23.67 | L32: 66.75 | M32: 1816.99 | P32: =IF(O32="","",IF(F32>O32,"Above","Below")) | Q32: 221208 | R32: 0 | S32: 0 | T32: 0 | U32: 0
... A50: 44540 | B50: =TEXT(A50,"ddd") | C50: 1776.3 | D50: 1791 | E50: 1770.4 | F50: 1784.8 | G50: =F50-F49 | H50: =IF(F49=0,0,G50/F49) | I50: =D50-E50 | J50: =IF(F50>C50,"Up",IF(F50<C50,"Down","Flat")) | K50: 22.86 | L50: 45.04 | M50: 1793.89 | P50: =IF(O50="","",IF(F50>O50,"Above","Below")) | Q50: 141995 | R50: 0 | S50: 0 | T50: 0 | U50: 0
A51: 44543 | B51: =TEXT(A51,"ddd") | C51: 1784.2 | D51: 1792.8 | E51: 1782.2 | F51: 1788.3 | G51: =F51-F50 | H51: =IF(F50=0,0,G51/F50) | I51: =D51-E51 | J51: =IF(F51>C51,"Up",IF(F51<C51,"Down","Flat")) | K51: 21.99 | L51: 46.4 | M51: 1793.36 | N51: 1794.23 | P51: =IF(O51="","",IF(F51>O51,"Above","Below")) | Q51: 106057 | R51: 0 | S51: 0 | T51: 0 | U51: 0
A52: 44544 | B52: =TEXT(A52,"ddd") | C52: 1787.6 | D52: 1789.8 | E52: 1766.1 | F52: 1772.3 | G52: =F52-F51 | H52: =IF(F51=0,0,G52/F51) | I52: =D52-E52 | J52: =IF(F52>C52,"Up",IF(F52<C52,"Down","Flat")) | K52: 22.11 | L52: 41.37 | M52: 1791.35 | N52: 1793.37 | P52: =IF(O52="","",IF(F52>O52,"Above","Below")) | Q52: 153249 | R52: 0 | S52: 0 | T52: 0 | U52: 0
A53: 44545 | B53: =TEXT(A53,"ddd") | C53: 1771.9 | D53: 1781.3 | E53: 1753 | F53: 1764.5 | G53: =F53-F52 | H53: =IF(F52=0,0,G53/F52) | I53: =D53-E53 | J53: =IF(F53>C53,"Up",IF(F53<C53,"Down","Flat")) | K53: 22.55 | L53: 39.14 | M53: 1788.8 | N53: 1792.24 | P53: =IF(O53="","",IF(F53>O53,"Above","Below")) | Q53: 161101 | R53: 0 | S53: 0 | T53: 0 | U53: 0
A54: 44546 | B54: =TEXT(A54,"ddd") | C54: 1777.9 | D54: 1800.7 | E54: 1775.7 | F54: 1798.2 | G54: =F54-F53 | H54: =IF(F53=0,0,G54/F53) | I54: =D54-E54 | J54: =IF(F54>C54,"Up",IF(F54<C54,"Down","Flat")) | K54: 23.53 | L54: 51.33 | M54: 1789.69 | N54: 1792.48 | P54: =IF(O54="","",IF(F54>O54,"Above","Below")) | Q54: 167777 | R54: 0 | S54: 0 | T54: 0 | U54: 0
A55: 44547 | B55: =TEXT(A55,"ddd") | C55: 1801.5 | D55: 1815.7 | E55: 1796.5 | F55: 1804.9 | G55: =F55-F54 | H55: =IF(F54=0,0,G55/F54) | I55: =D55-E55 | J55: =IF(F55>C55,"Up",IF(F55<C55,"Down","Flat")) | K55: 23.22 | L55: 53.33 | M55: 1791.14 | N55: 1792.96 | P55: =IF(O55="","",IF(F55>O55,"Above","Below")) | Q55: 156607 | R55: 0 | S55: 0 | T55: 0 | U55: 0
A56: 44550 | B56: =TEXT(A56,"ddd") | C56: 1800.2 | D56: 1804.6 | E56: 1789 | F56: 1794.6 | G56: =F56-F55 | H56: =IF(F55=0,0,G56/F55) | I56: =D56-E56 | J56: =IF(F56>C56,"Up",IF(F56<C56,"Down","Flat")) | K56: 22.7 | L56: 49.93 | M56: 1791.47 | N56: 1793.03 | P56: =IF(O56="","",IF(F56>O56,"Above","Below")) | Q56: 105386 | R56: 0 | S56: 0 | T56: 0 | U56: 0
A57: 44551 | B57: =TEXT(A57,"ddd") | C57: 1791.4 | D57: 1801.7 | E57: 1785 | F57: 1788.7 | G57: =F57-F56 | H57: =IF(F56=0,0,G57/F56) | I57: =D57-E57 | J57: =IF(F57>C57,"Up",IF(F57<C57,"Down","Flat")) | K57: 22.27 | L57: 48.05 | M57: 1791.21 | N57: 1792.86 | P57: =IF(O57="","",IF(F57>O57,"Above","Below")) | Q57: 134154 | R57: 0 | S57: 0 | T57: 0 | U57: 0
...

Sheet Monthly
A1: Month | B1: Open ($) | C1: High ($) | D1: Low ($) | E1: Close ($) | F1: Change (%) | G1: Avg daily range ($) | H1: Up days | I1: Down days | J1: Trading days | K1: Signals | L1: Net R
A2: 44470 | B2: ='Daily log'!C2 | C2: =_xlfn.MAXIFS('Daily log'!D:D,'Daily log'!A:A,">="&A2,'Daily log'!A:A,"<"&EDATE(A2,1)) | D2: =_xlfn.MINIFS('Daily log'!E:E,'Daily log'!A:A,">="&A2,'Daily log'!A:A,"<"&EDATE(A2,1)) | E2: =INDEX('Daily log'!$F$2:$F$100000,MATCH(EDATE(A2,1)-1,'Daily log'!$A$2:$A$100000,1)) | F2: =E2/B2-1 | G2: =IFERROR(AVERAGEIFS('Daily log'!I:I,'Daily log'!A:A,">="&A2,'Daily log'!A:A,"<"&EDATE(A2,1)),"") | H2: =COUNTIFS('Daily log'!A:A,">="&A2,'Daily log'!A:A,"<"&EDATE(A2,1),'Daily log'!J:J,"Up") | I2: =COUNTIFS('Daily log'!A:A,">="&A2,'Daily log'!A:A,"<"&EDATE(A2,1),'Daily log'!J:J,"Down") | J2: =COUNTIFS('Daily log'!A:A,">="&A2,'Daily log'!A:A,"<"&EDATE(A2,1)) | K2: =SUMIFS('Daily log'!R:R,'Daily log'!A:A,">="&A2,'Daily log'!A:A,"<"&EDATE(A2,1)) | L2: =SUMIFS('Daily log'!U:U,'Daily log'!A:A,">="&A2,'Daily log'!A:A,"<"&EDATE(A2,1))
A3: 44501 | B3: =INDEX('Daily log'!$C$2:$C$100000,MATCH(A3-1,'Daily log'!$A$2:$A$100000,1)+1) | C3: =_xlfn.MAXIFS('Daily log'!D:D,'Daily log'!A:A,">="&A3,'Daily log'!A:A,"<"&EDATE(A3,1)) | D3: =_xlfn.MINIFS('Daily log'!E:E,'Daily log'!A:A,">="&A3,'Daily log'!A:A,"<"&EDATE(A3,1)) | E3: =INDEX('Daily log'!$F$2:$F$100000,MATCH(EDATE(A3,1)-1,'Daily log'!$A$2:$A$100000,1)) | F3: =IFERROR(E3/E2-1,E3/B3-1) | G3: =IFERROR(AVERAGEIFS('Daily log'!I:I,'Daily log'!A:A,">="&A3,'Daily log'!A:A,"<"&EDATE(A3,1)),"") | H3: =COUNTIFS('Daily log'!A:A,">="&A3,'Daily log'!A:A,"<"&EDATE(A3,1),'Daily log'!J:J,"Up") | I3: =COUNTIFS('Daily log'!A:A,">="&A3,'Daily log'!A:A,"<"&EDATE(A3,1),'Daily log'!J:J,"Down") | J3: =COUNTIFS('Daily log'!A:A,">="&A3,'Daily log'!A:A,"<"&EDATE(A3,1)) | K3: =SUMIFS('Daily log'!R:R,'Daily log'!A:A,">="&A3,'Daily log'!A:A,"<"&EDATE(A3,1)) | L3: =SUMIFS('Daily log'!U:U,'Daily log'!A:A,">="&A3,'Daily log'!A:A,"<"&EDATE(A3,1))
A4: 44531 | B4: =INDEX('Daily log'!$C$2:$C$100000,MATCH(A4-1,'Daily log'!$A$2:$A$100000,1)+1) | C4: =_xlfn.MAXIFS('Daily log'!D:D,'Daily log'!A:A,">="&A4,'Daily log'!A:A,"<"&EDATE(A4,1)) | D4: =_xlfn.MINIFS('Daily log'!E:E,'Daily log'!A:A,">="&A4,'Daily log'!A:A,"<"&EDATE(A4,1)) | E4: =INDEX('Daily log'!$F$2:$F$100000,MATCH(EDATE(A4,1)-1,'Daily log'!$A$2:$A$100000,1)) | F4: =IFERROR(E4/E3-1,E4/B4-1) | G4: =IFERROR(AVERAGEIFS('Daily log'!I:I,'Daily log'!A:A,">="&A4,'Daily log'!A:A,"<"&EDATE(A4,1)),"") | H4: =COUNTIFS('Daily log'!A:A,">="&A4,'Daily log'!A:A,"<"&EDATE(A4,1),'Daily log'!J:J,"Up") | I4: =COUNTIFS('Daily log'!A:A,">="&A4,'Daily log'!A:A,"<"&EDATE(A4,1),'Daily log'!J:J,"Down") | J4: =COUNTIFS('Daily log'!A:A,">="&A4,'Daily log'!A:A,"<"&EDATE(A4,1)) | K4: =SUMIFS('Daily log'!R:R,'Daily log'!A:A,">="&A4,'Daily log'!A:A,"<"&EDATE(A4,1)) | L4: =SUMIFS('Daily log'!U:U,'Daily log'!A:A,">="&A4,'Daily log'!A:A,"<"&EDATE(A4,1))
A5: 44562 | B5: =INDEX('Daily log'!$C$2:$C$100000,MATCH(A5-1,'Daily log'!$A$2:$A$100000,1)+1) | C5: =_xlfn.MAXIFS('Daily log'!D:D,'Daily log'!A:A,">="&A5,'Daily log'!A:A,"<"&EDATE(A5,1)) | D5: =_xlfn.MINIFS('Daily log'!E:E,'Daily log'!A:A,">="&A5,'Daily log'!A:A,"<"&EDATE(A5,1)) | E5: =INDEX('Daily log'!$F$2:$F$100000,MATCH(EDATE(A5,1)-1,'Daily log'!$A$2:$A$100000,1)) | F5: =IFERROR(E5/E4-1,E5/B5-1) | G5: =IFERROR(AVERAGEIFS('Daily log'!I:I,'Daily log'!A:A,">="&A5,'Daily log'!A:A,"<"&EDATE(A5,1)),"") | H5: =COUNTIFS('Daily log'!A:A,">="&A5,'Daily log'!A:A,"<"&EDATE(A5,1),'Daily log'!J:J,"Up") | I5: =COUNTIFS('Daily log'!A:A,">="&A5,'Daily log'!A:A,"<"&EDATE(A5,1),'Daily log'!J:J,"Down") | J5: =COUNTIFS('Daily log'!A:A,">="&A5,'Daily log'!A:A,"<"&EDATE(A5,1)) | K5: =SUMIFS('Daily log'!R:R,'Daily log'!A:A,">="&A5,'Daily log'!A:A,"<"&EDATE(A5,1)) | L5: =SUMIFS('Daily log'!U:U,'Daily log'!A:A,">="&A5,'Daily log'!A:A,"<"&EDATE(A5,1))
A6: 44593 | B6: =INDEX('Daily log'!$C$2:$C$100000,MATCH(A6-1,'Daily log'!$A$2:$A$100000,1)+1) | C6: =_xlfn.MAXIFS('Daily log'!D:D,'Daily log'!A:A,">="&A6,'Daily log'!A:A,"<"&EDATE(A6,1)) | D6: =_xlfn.MINIFS('Daily log'!E:E,'Daily log'!A:A,">="&A6,'Daily log'!A:A,"<"&EDATE(A6,1)) | E6: =INDEX('Daily log'!$F$2:$F$100000,MATCH(EDATE(A6,1)-1,'Daily log'!$A$2:$A$100000,1)) | F6: =IFERROR(E6/E5-1,E6/B6-1) | G6: =IFERROR(AVERAGEIFS('Daily log'!I:I,'Daily log'!A:A,">="&A6,'Daily log'!A:A,"<"&EDATE(A6,1)),"") | H6: =COUNTIFS('Daily log'!A:A,">="&A6,'Daily log'!A:A,"<"&EDATE(A6,1),'Daily log'!J:J,"Up") | I6: =COUNTIFS('Daily log'!A:A,">="&A6,'Daily log'!A:A,"<"&EDATE(A6,1),'Daily log'!J:J,"Down") | J6: =COUNTIFS('Daily log'!A:A,">="&A6,'Daily log'!A:A,"<"&EDATE(A6,1)) | K6: =SUMIFS('Daily log'!R:R,'Daily log'!A:A,">="&A6,'Daily log'!A:A,"<"&EDATE(A6,1)) | L6: =SUMIFS('Daily log'!U:U,'Daily log'!A:A,">="&A6,'Daily log'!A:A,"<"&EDATE(A6,1))
A7: 44621 | B7: =INDEX('Daily log'!$C$2:$C$100000,MATCH(A7-1,'Daily log'!$A$2:$A$100000,1)+1) | C7: =_xlfn.MAXIFS('Daily log'!D:D,'Daily log'!A:A,">="&A7,'Daily log'!A:A,"<"&EDATE(A7,1)) | D7: =_xlfn.MINIFS('Daily log'!E:E,'Daily log'!A:A,">="&A7,'Daily log'!A:A,"<"&EDATE(A7,1)) | E7: =INDEX('Daily log'!$F$2:$F$100000,MATCH(EDATE(A7,1)-1,'Daily log'!$A$2:$A$100000,1)) | F7: =IFERROR(E7/E6-1,E7/B7-1) | G7: =IFERROR(AVERAGEIFS('Daily log'!I:I,'Daily log'!A:A,">="&A7,'Daily log'!A:A,"<"&EDATE(A7,1)),"") | H7: =COUNTIFS('Daily log'!A:A,">="&A7,'Daily log'!A:A,"<"&EDATE(A7,1),'Daily log'!J:J,"Up") | I7: =COUNTIFS('Daily log'!A:A,">="&A7,'Daily log'!A:A,"<"&EDATE(A7,1),'Daily log'!J:J,"Down") | J7: =COUNTIFS('Daily log'!A:A,">="&A7,'Daily log'!A:A,"<"&EDATE(A7,1)) | K7: =SUMIFS('Daily log'!R:R,'Daily log'!A:A,">="&A7,'Daily log'!A:A,"<"&EDATE(A7,1)) | L7: =SUMIFS('Daily log'!U:U,'Daily log'!A:A,">="&A7,'Daily log'!A:A,"<"&EDATE(A7,1))
A8: 44652 | B8: =INDEX('Daily log'!$C$2:$C$100000,MATCH(A8-1,'Daily log'!$A$2:$A$100000,1)+1) | C8: =_xlfn.MAXIFS('Daily log'!D:D,'Daily log'!A:A,">="&A8,'Daily log'!A:A,"<"&EDATE(A8,1)) | D8: =_xlfn.MINIFS('Daily log'!E:E,'Daily log'!A:A,">="&A8,'Daily log'!A:A,"<"&EDATE(A8,1)) | E8: =INDEX('Daily log'!$F$2:$F$100000,MATCH(EDATE(A8,1)-1,'Daily log'!$A$2:$A$100000,1)) | F8: =IFERROR(E8/E7-1,E8/B8-1) | G8: =IFERROR(AVERAGEIFS('Daily log'!I:I,'Daily log'!A:A,">="&A8,'Daily log'!A:A,"<"&EDATE(A8,1)),"") | H8: =COUNTIFS('Daily log'!A:A,">="&A8,'Daily log'!A:A,"<"&EDATE(A8,1),'Daily log'!J:J,"Up") | I8: =COUNTIFS('Daily log'!A:A,">="&A8,'Daily log'!A:A,"<"&EDATE(A8,1),'Daily log'!J:J,"Down") | J8: =COUNTIFS('Daily log'!A:A,">="&A8,'Daily log'!A:A,"<"&EDATE(A8,1)) | K8: =SUMIFS('Daily log'!R:R,'Daily log'!A:A,">="&A8,'Daily log'!A:A,"<"&EDATE(A8,1)) | L8: =SUMIFS('Daily log'!U:U,'Daily log'!A:A,">="&A8,'Daily log'!A:A,"<"&EDATE(A8,1))
A9: 44682 | B9: =INDEX('Daily log'!$C$2:$C$100000,MATCH(A9-1,'Daily log'!$A$2:$A$100000,1)+1) | C9: =_xlfn.MAXIFS('Daily log'!D:D,'Daily log'!A:A,">="&A9,'Daily log'!A:A,"<"&EDATE(A9,1)) | D9: =_xlfn.MINIFS('Daily log'!E:E,'Daily log'!A:A,">="&A9,'Daily log'!A:A,"<"&EDATE(A9,1)) | E9: =INDEX('Daily log'!$F$2:$F$100000,MATCH(EDATE(A9,1)-1,'Daily log'!$A$2:$A$100000,1)) | F9: =IFERROR(E9/E8-1,E9/B9-1) | G9: =IFERROR(AVERAGEIFS('Daily log'!I:I,'Daily log'!A:A,">="&A9,'Daily log'!A:A,"<"&EDATE(A9,1)),"") | H9: =COUNTIFS('Daily log'!A:A,">="&A9,'Daily log'!A:A,"<"&EDATE(A9,1),'Daily log'!J:J,"Up") | I9: =COUNTIFS('Daily log'!A:A,">="&A9,'Daily log'!A:A,"<"&EDATE(A9,1),'Daily log'!J:J,"Down") | J9: =COUNTIFS('Daily log'!A:A,">="&A9,'Daily log'!A:A,"<"&EDATE(A9,1)) | K9: =SUMIFS('Daily log'!R:R,'Daily log'!A:A,">="&A9,'Daily log'!A:A,"<"&EDATE(A9,1)) | L9: =SUMIFS('Daily log'!U:U,'Daily log'!A:A,">="&A9,'Daily log'!A:A,"<"&EDATE(A9,1))
A10: 44713 | B10: =INDEX('Daily log'!$C$2:$C$100000,MATCH(A10-1,'Daily log'!$A$2:$A$100000,1)+1) | C10: =_xlfn.MAXIFS('Daily log'!D:D,'Daily log'!A:A,">="&A10,'Daily log'!A:A,"<"&EDATE(A10,1)) | D10: =_xlfn.MINIFS('Daily log'!E:E,'Daily log'!A:A,">="&A10,'Daily log'!A:A,"<"&EDATE(A10,1)) | E10: =INDEX('Daily log'!$F$2:$F$100000,MATCH(EDATE(A10,1)-1,'Daily log'!$A$2:$A$100000,1)) | F10: =IFERROR(E10/E9-1,E10/B10-1) | G10: =IFERROR(AVERAGEIFS('Daily log'!I:I,'Daily log'!A:A,">="&A10,'Daily log'!A:A,"<"&EDATE(A10,1)),"") | H10: =COUNTIFS('Daily log'!A:A,">="&A10,'Daily log'!A:A,"<"&EDATE(A10,1),'Daily log'!J:J,"Up") | I10: =COUNTIFS('Daily log'!A:A,">="&A10,'Daily log'!A:A,"<"&EDATE(A10,1),'Daily log'!J:J,"Down") | J10: =COUNTIFS('Daily log'!A:A,">="&A10,'Daily log'!A:A,"<"&EDATE(A10,1)) | K10: =SUMIFS('Daily log'!R:R,'Daily log'!A:A,">="&A10,'Daily log'!A:A,"<"&EDATE(A10,1)) | L10: =SUMIFS('Daily log'!U:U,'Daily log'!A:A,">="&A10,'Daily log'!A:A,"<"&EDATE(A10,1))
A11: 44743 | B11: =INDEX('Daily log'!$C$2:$C$100000,MATCH(A11-1,'Daily log'!$A$2:$A$100000,1)+1) | C11: =_xlfn.MAXIFS('Daily log'!D:D,'Daily log'!A:A,">="&A11,'Daily log'!A:A,"<"&EDATE(A11,1)) | D11: =_xlfn.MINIFS('Daily log'!E:E,'Daily log'!A:A,">="&A11,'Daily log'!A:A,"<"&EDATE(A11,1)) | E11: =INDEX('Daily log'!$F$2:$F$100000,MATCH(EDATE(A11,1)-1,'Daily log'!$A$2:$A$100000,1)) | F11: =IFERROR(E11/E10-1,E11/B11-1) | G11: =IFERROR(AVERAGEIFS('Daily log'!I:I,'Daily log'!A:A,">="&A11,'Daily log'!A:A,"<"&EDATE(A11,1)),"") | H11: =COUNTIFS('Daily log'!A:A,">="&A11,'Daily log'!A:A,"<"&EDATE(A11,1),'Daily log'!J:J,"Up") | I11: =COUNTIFS('Daily log'!A:A,">="&A11,'Daily log'!A:A,"<"&EDATE(A11,1),'Daily log'!J:J,"Down") | J11: =COUNTIFS('Daily log'!A:A,">="&A11,'Daily log'!A:A,"<"&EDATE(A11,1)) | K11: =SUMIFS('Daily log'!R:R,'Daily log'!A:A,">="&A11,'Daily log'!A:A,"<"&EDATE(A11,1)) | L11: =SUMIFS('Daily log'!U:U,'Daily log'!A:A,">="&A11,'Daily log'!A:A,"<"&EDATE(A11,1))
A12: 44774 | B12: =INDEX('Daily log'!$C$2:$C$100000,MATCH(A12-1,'Daily log'!$A$2:$A$100000,1)+1) | C12: =_xlfn.MAXIFS('Daily log'!D:D,'Daily log'!A:A,">="&A12,'Daily log'!A:A,"<"&EDATE(A12,1)) | D12: =_xlfn.MINIFS('Daily log'!E:E,'Daily log'!A:A,">="&A12,'Daily log'!A:A,"<"&EDATE(A12,1)) | E12: =INDEX('Daily log'!$F$2:$F$100000,MATCH(EDATE(A12,1)-1,'Daily log'!$A$2:$A$100000,1)) | F12: =IFERROR(E12/E11-1,E12/B12-1) | G12: =IFERROR(AVERAGEIFS('Daily log'!I:I,'Daily log'!A:A,">="&A12,'Daily log'!A:A,"<"&EDATE(A12,1)),"") | H12: =COUNTIFS('Daily log'!A:A,">="&A12,'Daily log'!A:A,"<"&EDATE(A12,1),'Daily log'!J:J,"Up") | I12: =COUNTIFS('Daily log'!A:A,">="&A12,'Daily log'!A:A,"<"&EDATE(A12,1),'Daily log'!J:J,"Down") | J12: =COUNTIFS('Daily log'!A:A,">="&A12,'Daily log'!A:A,"<"&EDATE(A12,1)) | K12: =SUMIFS('Daily log'!R:R,'Daily log'!A:A,">="&A12,'Daily log'!A:A,"<"&EDATE(A12,1)) | L12: =SUMIFS('Daily log'!U:U,'Daily log'!A:A,">="&A12,'Daily log'!A:A,"<"&EDATE(A12,1))
A13: 44805 | B13: =INDEX('Daily log'!$C$2:$C$100000,MATCH(A13-1,'Daily log'!$A$2:$A$100000,1)+1) | C13: =_xlfn.MAXIFS('Daily log'!D:D,'Daily log'!A:A,">="&A13,'Daily log'!A:A,"<"&EDATE(A13,1)) | D13: =_xlfn.MINIFS('Daily log'!E:E,'Daily log'!A:A,">="&A13,'Daily log'!A:A,"<"&EDATE(A13,1)) | E13: =INDEX('Daily log'!$F$2:$F$100000,MATCH(EDATE(A13,1)-1,'Daily log'!$A$2:$A$100000,1)) | F13: =IFERROR(E13/E12-1,E13/B13-1) | G13: =IFERROR(AVERAGEIFS('Daily log'!I:I,'Daily log'!A:A,">="&A13,'Daily log'!A:A,"<"&EDATE(A13,1)),"") | H13: =COUNTIFS('Daily log'!A:A,">="&A13,'Daily log'!A:A,"<"&EDATE(A13,1),'Daily log'!J:J,"Up") | I13: =COUNTIFS('Daily log'!A:A,">="&A13,'Daily log'!A:A,"<"&EDATE(A13,1),'Daily log'!J:J,"Down") | J13: =COUNTIFS('Daily log'!A:A,">="&A13,'Daily log'!A:A,"<"&EDATE(A13,1)) | K13: =SUMIFS('Daily log'!R:R,'Daily log'!A:A,">="&A13,'Daily log'!A:A,"<"&EDATE(A13,1)) | L13: =SUMIFS('Daily log'!U:U,'Daily log'!A:A,">="&A13,'Daily log'!A:A,"<"&EDATE(A13,1))
A14: 44835 | B14: =INDEX('Daily log'!$C$2:$C$100000,MATCH(A14-1,'Daily log'!$A$2:$A$100000,1)+1) | C14: =_xlfn.MAXIFS('Daily log'!D:D,'Daily log'!A:A,">="&A14,'Daily log'!A:A,"<"&EDATE(A14,1)) | D14: =_xlfn.MINIFS('Daily log'!E:E,'Daily log'!A:A,">="&A14,'Daily log'!A:A,"<"&EDATE(A14,1)) | E14: =INDEX('Daily log'!$F$2:$F$100000,MATCH(EDATE(A14,1)-1,'Daily log'!$A$2:$A$100000,1)) | F14: =IFERROR(E14/E13-1,E14/B14-1) | G14: =IFERROR(AVERAGEIFS('Daily log'!I:I,'Daily log'!A:A,">="&A14,'Daily log'!A:A,"<"&EDATE(A14,1)),"") | H14: =COUNTIFS('Daily log'!A:A,">="&A14,'Daily log'!A:A,"<"&EDATE(A14,1),'Daily log'!J:J,"Up") | I14: =COUNTIFS('Daily log'!A:A,">="&A14,'Daily log'!A:A,"<"&EDATE(A14,1),'Daily log'!J:J,"Down") | J14: =COUNTIFS('Daily log'!A:A,">="&A14,'Daily log'!A:A,"<"&EDATE(A14,1)) | K14: =SUMIFS('Daily log'!R:R,'Daily log'!A:A,">="&A14,'Daily log'!A:A,"<"&EDATE(A14,1)) | L14: =SUMIFS('Daily log'!U:U,'Daily log'!A:A,">="&A14,'Daily log'!A:A,"<"&EDATE(A14,1))
... A62: 46296 | B62: =INDEX('Daily log'!$C$2:$C$100000,MATCH(A62-1,'Daily log'!$A$2:$A$100000,1)+1) | C62: =_xlfn.MAXIFS('Daily log'!D:D,'Daily log'!A:A,">="&A62,'Daily log'!A:A,"<"&EDATE(A62,1)) | D62: =_xlfn.MINIFS('Daily log'!E:E,'Daily log'!A:A,">="&A62,'Daily log'!A:A,"<"&EDATE(A62,1)) | E62: =INDEX('Daily log'!$F$2:$F$100000,MATCH(EDATE(A62,1)-1,'Daily log'!$A$2:$A$100000,1)) | F62: =IFERROR(E62/E61-1,E62/B62-1) | G62: =IFERROR(AVERAGEIFS('Daily log'!I:I,'Daily log'!A:A,">="&A62,'Daily log'!A:A,"<"&EDATE(A62,1)),"") | H62: =COUNTIFS('Daily log'!A:A,">="&A62,'Daily log'!A:A,"<"&EDATE(A62,1),'Daily log'!J:J,"Up") | I62: =COUNTIFS('Daily log'!A:A,">="&A62,'Daily log'!A:A,"<"&EDATE(A62,1),'Daily log'!J:J,"Down") | J62: =COUNTIFS('Daily log'!A:A,">="&A62,'Daily log'!A:A,"<"&EDATE(A62,1)) | K62: =SUMIFS('Daily log'!R:R,'Daily log'!A:A,">="&A62,'Daily log'!A:A,"<"&EDATE(A62,1)) | L62: =SUMIFS('Daily log'!U:U,'Daily log'!A:A,">="&A62,'Daily log'!A:A,"<"&EDATE(A62,1))

Sheet Read me
A1: What this is | B1: A daily record of gold (XAUUSD) prices, updated automatically after each trading day.
A2: Price source | B2: Spot XAU/USD (Twelve Data)
A3: Volume | B3: COMEX gold futures daily volume (Yahoo). Blank when unavailable.
A4: Signals, Wins, Losses, Net R | B4: From the gold-agent journal: LONG/SHORT signals that fired that day (UTC date).
A5: Blue numbers | B5: Imported data: prices, indicators, volume, signals.
A6: Black cells | B6: Formulas: changes, range, direction, trend, and everything on Summary and Monthly.
A7: Indicators | B7: EMA 20/50/200, RSI 14 and ATR 14 on daily candles. Blank until enough history exists.
A8: Download | B8: Latest copy: basemayman-ux.github.io/gold-agent/data/XAUUSD_daily_log.xlsx
A9: Your own notes | B9: This file is rebuilt every day. Save a copy before adding your own notes.
